<?xml version="1.0"?>

<robot xmlns="http://drake.mit.edu"
 xmlns:xsi="http://www.w3.org/2001/XMLSchema-instance"
 name="CartPole">

  <link name="ground">
    <visual>
      <origin xyz="0 0 0" rpy="0 0 0" />
      <geometry>
        <box size="1000 1000 10" />
      </geometry>
      <material>
        <color rgba="0.93 .74 .4 1" />
      </material>
    </visual>
    <inertial>
      <pose frame=''>0 0 0 0 0 0</pose>
      <mass>0</mass>
      <inertia>
        <ixx>0</ixx>
        <ixy>0</ixy>
        <ixz>0</ixz>
        <iyy>0</iyy>
        <iyz>0</iyz>
        <izz>0</izz>
      </inertia>
    </inertial>
  </link>

  <link name="cube">
    <inertial>
      <pose frame=''>0 0 0 0 0 0</pose>
      <mass>10.0</mass>
      <inertia>
        <ixx>1.0</ixx>
        <ixy>0</ixy>
        <ixz>0</ixz>
        <iyy>1.0</iyy>
        <iyz>0</iyz>
        <izz>1.0</izz>
      </inertia>
    </inertial>
    <collision name='cube_collision'>
      <origin xyz="0 0 0" rpy="0 0 0"/>
      <geometry>
        <box size=".5 .5 .5" />
      </geometry>
    </collision>
    <visual>
      <origin xyz="0 0 0" rpy="0 0 0" />
      <geometry>
        <box size=".5 .5 .5" />
      </geometry>
      <material>
        <color rgba="0 0 1 1" />
      </material>
    </visual>
  </link>

  <link name="wheel">
  	<inertial>
      <origin rpy="1.5707963267948966 0 0"/>
  		<mass value="1.0"/>
  		<inertia ixx="1" iyy="1" izz="1" ixy="0.0" ixz="0.0" iyz="0.0"/>
  	</inertial>
  	<visual>
      <origin rpy="1.5707963267948966 0 0"/>
      <geometry>
        <cylinder radius="0.15" length=".25"/>
      </geometry>
    </visual>
  </link>

  <joint name="cube_position" type="floating">
    <parent link="ground" />
    <child link="cube" />
    <origin xyz="0 0 .25"/>
    <axis xyz="1 0 0" />
    <dynamics damping="0.1" />
  </joint>

  <joint name="theta" type="continuous">
    <parent link="cube" />
    <child link="wheel" />
    <origin xyz="0 0 0" />
    <axis>
      <xyz>1 0 0</xyz>
      <limit>
        <effort>0.0</effort>
      </limit>
      <dynamics>
        <damping>0</damping>
        <friction>0</friction>
        <spring_reference>0</spring_reference>
        <spring_stiffness>0</spring_stiffness>
      </dynamics>
      <use_parent_model_frame>1</use_parent_model_frame>
    </axis>
    <dynamics damping="0.1" />
  </joint>

  <transmission type="SimpleTransmission" name="cube_force">
    <actuator name="force" />
    <joint name="theta" />
    <mechanicalReduction>1</mechanicalReduction>
  </transmission>
</robot>
